2016-05-20 08:25:43,601 [Thread-8:123145314922496] [django.request:182] [base:get_response] [WARNING]- Not Found: /inc/timming.php
2016-05-21 15:18:35,327 [Thread-9:123145314922496] [django.request:170] [base:get_response] [WARNING]- Not Found: /inc/timming.php
2016-05-21 15:18:35,555 [Thread-10:123145310715904] [django.request:170] [base:get_response] [WARNING]- Not Found: /favicon.ico
2016-05-21 15:18:35,674 [Thread-11:123145310715904] [django.request:170] [base:get_response] [WARNING]- Not Found: /favicon.ico
2016-05-21 15:29:23,363 [Thread-26:123145310715904] [django.request:170] [base:get_response] [WARNING]- Not Found: /inc/timming.php
2016-05-21 15:29:50,401 [Thread-37:123145310715904] [django.request:170] [base:get_response] [WARNING]- Not Found: /inc/timming.php
2016-05-21 18:04:18,921 [Thread-44:123145310715904] [django.request:170] [base:get_response] [WARNING]- Not Found: /inc/timming.php
2016-05-21 19:17:03,214 [Thread-58:123145310715904] [django.request:170] [base:get_response] [WARNING]- Not Found: /inc/timming.php
2016-05-22 04:54:53,522 [Thread-7:123145310715904] [django.request:170] [base:get_response] [WARNING]- Not Found: /inc/timming.php
2016-05-22 04:54:53,625 [Thread-10:123145310715904] [django.request:170] [base:get_response] [WARNING]- Not Found: /favicon.ico
2016-05-22 04:54:53,659 [Thread-11:123145310715904] [django.request:170] [base:get_response] [WARNING]- Not Found: /favicon.ico
2016-06-04 13:15:40,122 [Thread-2:123145310715904] [django.request:170] [base:get_response] [WARNING]- Not Found: /assets/css/bootstrap-responsive.css
2016-06-04 13:15:46,969 [Thread-5:123145323335680] [django.request:170] [base:get_response] [WARNING]- Not Found: /assets/css/bootstrap-responsive.css
2016-06-04 13:16:04,282 [Thread-11:123145319129088] [django.request:170] [base:get_response] [WARNING]- Not Found: /assets/css/bootstrap-responsive.css
2016-06-04 13:16:09,115 [Thread-28:123145335955456] [django.request:170] [base:get_response] [WARNING]- Not Found: /inc/timming.php
2016-06-04 13:16:09,146 [Thread-29:123145335955456] [django.request:170] [base:get_response] [WARNING]- Not Found: /favicon.ico
2016-06-04 13:16:21,777 [Thread-16:123145314922496] [django.request:170] [base:get_response] [WARNING]- Not Found: /assets/css/bootstrap-responsive.css
2016-06-04 13:16:43,605 [Thread-32:123145319129088] [django.request:170] [base:get_response] [WARNING]- Not Found: /assets/css/bootstrap-responsive.css
2016-06-04 13:16:46,342 [Thread-38:123145319129088] [django.request:170] [base:get_response] [WARNING]- Not Found: /assets/css/bootstrap-responsive.css
2016-06-04 13:16:53,346 [Thread-42:123145310715904] [django.request:170] [base:get_response] [WARNING]- Not Found: /assets/css/bootstrap-responsive.css
2016-06-04 13:16:53,508 [Thread-43:123145314922496] [django.request:170] [base:get_response] [WARNING]- Not Found: /assets/ico/favicon.png
2016-06-04 13:16:56,570 [Thread-46:123145327542272] [django.request:170] [base:get_response] [WARNING]- Not Found: /assets/css/bootstrap-responsive.css
2016-06-04 13:16:57,851 [Thread-52:123145319129088] [django.request:170] [base:get_response] [WARNING]- Not Found: /assets/css/bootstrap-responsive.css
2016-06-04 13:17:52,964 [Thread-63:123145319129088] [django.request:170] [base:get_response] [WARNING]- Not Found: /inc/timming.php
2016-06-04 13:17:53,020 [Thread-64:123145310715904] [django.request:170] [base:get_response] [WARNING]- Not Found: /favicon.ico
2016-06-04 13:18:04,837 [Thread-70:123145331748864] [django.request:170] [base:get_response] [WARNING]- Not Found: /inc/timming.php
2016-06-04 13:18:37,624 [Thread-84:123145340162048] [django.request:170] [base:get_response] [WARNING]- Not Found: /inc/timming.php
2016-06-04 13:18:48,185 [Thread-85:123145310715904] [django.request:170] [base:get_response] [WARNING]- Not Found: /inc/timming.php
2016-06-05 12:33:20,311 [Thread-9:123145310715904] [django.request:170] [base:get_response] [WARNING]- Not Found: /inc/timming.php
2016-06-05 12:35:55,226 [Thread-17:123145310715904] [django.request:170] [base:get_response] [WARNING]- Not Found: /inc/timming.php
2016-06-05 12:35:59,246 [Thread-19:123145310715904] [django.request:170] [base:get_response] [WARNING]- Not Found: /inc/timming.php
2016-06-05 12:39:14,924 [Thread-27:123145310715904] [django.request:170] [base:get_response] [WARNING]- Not Found: /inc/timming.php
2016-06-05 13:09:11,652 [Thread-35:123145310715904] [django.request:170] [base:get_response] [WARNING]- Not Found: /inc/timming.php
2016-06-05 13:09:19,113 [Thread-36:123145310715904] [django.request:170] [base:get_response] [WARNING]- Not Found: /inc/timming.php
2016-06-05 13:09:49,454 [Thread-44:123145310715904] [django.request:170] [base:get_response] [WARNING]- Not Found: /inc/timming.php
2016-06-05 13:09:50,782 [Thread-52:123145310715904] [django.request:170] [base:get_response] [WARNING]- Not Found: /inc/timming.php
2016-06-05 13:10:48,784 [Thread-60:123145310715904] [django.request:170] [base:get_response] [WARNING]- Not Found: /inc/timming.php
2016-06-05 13:13:22,023 [Thread-68:123145310715904] [django.request:170] [base:get_response] [WARNING]- Not Found: /inc/timming.php
2016-06-05 13:20:35,451 [Thread-76:123145310715904] [django.request:170] [base:get_response] [WARNING]- Not Found: /inc/timming.php
2016-06-05 13:20:42,459 [Thread-77:123145310715904] [django.request:170] [base:get_response] [WARNING]- Not Found: /work.html
2016-06-05 13:25:34,742 [Thread-2:123145310715904] [django.request:256] [base:handle_uncaught_exception] [ERROR]- Internal Server Error: /
Traceback (most recent call last):
  File "/Library/Python/2.7/site-packages/Django-1.8.9-py2.7.egg/django/core/handlers/base.py", line 132, in get_response
    response = wrapped_callback(request, *callback_args, **callback_kwargs)
  File "/Users/ZZJMAC/PycharmProjects/DGCMDB/website/views.py", line 10, in index
    return render(request,'index.html',locals())
  File "/Library/Python/2.7/site-packages/Django-1.8.9-py2.7.egg/django/shortcuts.py", line 67, in render
    template_name, context, request=request, using=using)
  File "/Library/Python/2.7/site-packages/Django-1.8.9-py2.7.egg/django/template/loader.py", line 98, in render_to_string
    template = get_template(template_name, using=using)
  File "/Library/Python/2.7/site-packages/Django-1.8.9-py2.7.egg/django/template/loader.py", line 46, in get_template
    raise TemplateDoesNotExist(template_name)
TemplateDoesNotExist: index.html
2016-06-05 13:25:44,823 [Thread-3:123145310715904] [django.request:170] [base:get_response] [WARNING]- Not Found: /work.html
2016-06-05 13:26:11,132 [Thread-3:123145310715904] [django.request:170] [base:get_response] [WARNING]- Not Found: /css/menu.css
2016-06-05 13:26:11,143 [Thread-4:123145314922496] [django.request:170] [base:get_response] [WARNING]- Not Found: /js/jquery.js
2016-06-05 13:26:11,151 [Thread-5:123145310715904] [django.request:170] [base:get_response] [WARNING]- Not Found: /js/js.js
2016-06-05 13:26:11,157 [Thread-6:123145314922496] [django.request:170] [base:get_response] [WARNING]- Not Found: /js/home.js
2016-06-05 13:26:11,213 [Thread-7:123145310715904] [django.request:170] [base:get_response] [WARNING]- Not Found: /js/jquery.js
2016-06-05 13:26:11,235 [Thread-8:123145310715904] [django.request:170] [base:get_response] [WARNING]- Not Found: /js/js.js
2016-06-05 13:26:11,267 [Thread-9:123145310715904] [django.request:170] [base:get_response] [WARNING]- Not Found: /js/home.js
2016-06-05 13:26:13,343 [Thread-11:123145310715904] [django.request:170] [base:get_response] [WARNING]- Not Found: /css/menu.css
2016-06-05 13:26:13,351 [Thread-12:123145314922496] [django.request:170] [base:get_response] [WARNING]- Not Found: /js/jquery.js
2016-06-05 13:26:13,365 [Thread-13:123145319129088] [django.request:170] [base:get_response] [WARNING]- Not Found: /js/js.js
2016-06-05 13:26:13,375 [Thread-14:123145310715904] [django.request:170] [base:get_response] [WARNING]- Not Found: /js/home.js
2016-06-05 13:26:13,393 [Thread-15:123145310715904] [django.request:170] [base:get_response] [WARNING]- Not Found: /js/jquery.js
2016-06-05 13:26:13,405 [Thread-16:123145310715904] [django.request:170] [base:get_response] [WARNING]- Not Found: /js/js.js
2016-06-05 13:26:13,414 [Thread-17:123145310715904] [django.request:170] [base:get_response] [WARNING]- Not Found: /js/home.js
2016-06-05 13:29:02,115 [Thread-19:123145310715904] [django.request:170] [base:get_response] [WARNING]- Not Found: /css/menu.css
2016-06-05 13:29:02,121 [Thread-20:123145314922496] [django.request:170] [base:get_response] [WARNING]- Not Found: /js/jquery.js
2016-06-05 13:29:02,129 [Thread-21:123145319129088] [django.request:170] [base:get_response] [WARNING]- Not Found: /js/js.js
2016-06-05 13:29:02,131 [Thread-22:123145310715904] [django.request:170] [base:get_response] [WARNING]- Not Found: /js/home.js
2016-06-05 13:29:02,146 [Thread-23:123145310715904] [django.request:170] [base:get_response] [WARNING]- Not Found: /js/jquery.js
2016-06-05 13:29:49,436 [Thread-3:123145310715904] [django.request:170] [base:get_response] [WARNING]- Not Found: /js/js.js
2016-06-05 13:29:49,444 [Thread-4:123145314922496] [django.request:170] [base:get_response] [WARNING]- Not Found: /js/home.js
2016-06-05 13:29:49,451 [Thread-5:123145310715904] [django.request:170] [base:get_response] [WARNING]- Not Found: /css/menu.css
2016-06-05 13:29:49,452 [Thread-6:123145314922496] [django.request:170] [base:get_response] [WARNING]- Not Found: /js/jquery.js
2016-06-05 13:29:49,538 [Thread-7:123145310715904] [django.request:170] [base:get_response] [WARNING]- Not Found: /js/jquery.js
2016-06-05 13:29:49,553 [Thread-8:123145310715904] [django.request:170] [base:get_response] [WARNING]- Not Found: /js/js.js
2016-06-05 13:29:49,568 [Thread-9:123145310715904] [django.request:170] [base:get_response] [WARNING]- Not Found: /js/home.js
2016-06-05 13:30:59,264 [Thread-3:123145310715904] [django.request:170] [base:get_response] [WARNING]- Not Found: /css/menu.css
2016-06-05 13:30:59,272 [Thread-4:123145314922496] [django.request:170] [base:get_response] [WARNING]- Not Found: /js/jquery.js
2016-06-05 13:30:59,278 [Thread-5:123145310715904] [django.request:170] [base:get_response] [WARNING]- Not Found: /js/js.js
2016-06-05 13:30:59,280 [Thread-6:123145319129088] [django.request:170] [base:get_response] [WARNING]- Not Found: /js/home.js
2016-06-05 13:30:59,338 [Thread-7:123145310715904] [django.request:170] [base:get_response] [WARNING]- Not Found: /js/jquery.js
2016-06-05 13:30:59,361 [Thread-8:123145310715904] [django.request:170] [base:get_response] [WARNING]- Not Found: /js/js.js
2016-06-05 13:30:59,394 [Thread-9:123145310715904] [django.request:170] [base:get_response] [WARNING]- Not Found: /js/home.js
2016-06-05 13:31:45,361 [Thread-9:123145310715904] [django.request:170] [base:get_response] [WARNING]- Not Found: /inc/timming.php
2016-06-05 13:31:50,056 [Thread-11:123145310715904] [django.request:170] [base:get_response] [WARNING]- Not Found: /inc/timming.php
2016-06-05 13:32:43,610 [Thread-14:123145310715904] [django.request:170] [base:get_response] [WARNING]- Not Found: /inc/timming.php
2016-06-05 13:32:47,179 [Thread-15:123145310715904] [django.request:170] [base:get_response] [WARNING]- Not Found: /ApplyCertificate.html
2016-06-05 13:32:51,383 [Thread-16:123145310715904] [django.request:170] [base:get_response] [WARNING]- Not Found: /ApplyCertificate.html
2016-06-05 13:32:52,419 [Thread-17:123145310715904] [django.request:170] [base:get_response] [WARNING]- Not Found: /ApplyCertificate.html
2016-06-05 13:32:53,083 [Thread-18:123145310715904] [django.request:170] [base:get_response] [WARNING]- Not Found: /ApplyCertificate.html
2016-06-05 13:32:53,611 [Thread-19:123145310715904] [django.request:170] [base:get_response] [WARNING]- Not Found: /ApplyCertificate.html
2016-06-05 13:32:54,015 [Thread-20:123145310715904] [django.request:170] [base:get_response] [WARNING]- Not Found: /ApplyCertificate.html
2016-06-05 13:32:55,028 [Thread-21:123145310715904] [django.request:170] [base:get_response] [WARNING]- Not Found: /ApplyCertificate.html
2016-06-05 13:32:56,021 [Thread-22:123145310715904] [django.request:170] [base:get_response] [WARNING]- Not Found: /ApplyCertificate.html
2016-06-05 13:32:56,987 [Thread-23:123145310715904] [django.request:170] [base:get_response] [WARNING]- Not Found: /ApplyCertificate.html
2016-06-05 13:32:57,732 [Thread-24:123145310715904] [django.request:170] [base:get_response] [WARNING]- Not Found: /ApplyCertificate.html
2016-06-05 13:32:59,435 [Thread-25:123145310715904] [django.request:170] [base:get_response] [WARNING]- Not Found: /ApplyCertificate.html
2016-06-05 13:33:51,848 [Thread-26:123145310715904] [django.request:170] [base:get_response] [WARNING]- Not Found: /ApplyCertificate.html
2016-06-05 13:33:55,693 [Thread-28:123145310715904] [django.request:170] [base:get_response] [WARNING]- Not Found: /inc/timming.php
2016-06-05 13:33:58,094 [Thread-30:123145310715904] [django.request:170] [base:get_response] [WARNING]- Not Found: /inc/timming.php
2016-06-05 13:34:27,857 [Thread-32:123145310715904] [django.request:170] [base:get_response] [WARNING]- Not Found: /inc/timming.php
2016-06-05 13:34:29,469 [Thread-40:123145310715904] [django.request:170] [base:get_response] [WARNING]- Not Found: /inc/timming.php
2016-06-05 13:34:30,448 [Thread-48:123145310715904] [django.request:170] [base:get_response] [WARNING]- Not Found: /inc/timming.php
2016-06-05 13:34:33,066 [Thread-49:123145310715904] [django.request:170] [base:get_response] [WARNING]- Not Found: /ApplyCertificate.html
2016-06-05 13:35:23,093 [Thread-51:123145310715904] [django.request:170] [base:get_response] [WARNING]- Not Found: /inc/timming.php
2016-06-05 13:35:25,259 [Thread-52:123145310715904] [django.request:170] [base:get_response] [WARNING]- Not Found: /active/ApplyCertificate.html
2016-06-05 13:37:01,075 [Thread-60:123145310715904] [django.request:170] [base:get_response] [WARNING]- Not Found: /inc/timming.php
2016-06-05 13:37:06,029 [Thread-62:123145310715904] [django.request:170] [base:get_response] [WARNING]- Not Found: /inc/timming.php
2016-06-05 13:37:09,682 [Thread-64:123145310715904] [django.request:170] [base:get_response] [WARNING]- Not Found: /inc/timming.php
2016-06-05 13:37:13,507 [Thread-66:123145310715904] [django.request:170] [base:get_response] [WARNING]- Not Found: /inc/timming.php
2016-06-05 13:40:59,090 [Thread-74:123145310715904] [django.request:170] [base:get_response] [WARNING]- Not Found: /inc/timming.php
2016-06-05 16:14:19,209 [Thread-82:123145310715904] [django.request:170] [base:get_response] [WARNING]- Not Found: /inc/timming.php
2016-06-10 03:08:48,857 [Thread-2:123145310715904] [django.request:256] [base:handle_uncaught_exception] [ERROR]- Internal Server Error: /
Traceback (most recent call last):
  File "/Library/Python/2.7/site-packages/Django-1.8.9-py2.7.egg/django/core/handlers/base.py", line 119, in get_response
    resolver_match = resolver.resolve(request.path_info)
  File "/Library/Python/2.7/site-packages/Django-1.8.9-py2.7.egg/django/core/urlresolvers.py", line 365, in resolve
    for pattern in self.url_patterns:
  File "/Library/Python/2.7/site-packages/Django-1.8.9-py2.7.egg/django/core/urlresolvers.py", line 401, in url_patterns
    patterns = getattr(self.urlconf_module, "urlpatterns", self.urlconf_module)
  File "/Library/Python/2.7/site-packages/Django-1.8.9-py2.7.egg/django/core/urlresolvers.py", line 395, in urlconf_module
    self._urlconf_module = import_module(self.urlconf_name)
  File "/System/Library/Frameworks/Python.framework/Versions/2.7/lib/python2.7/importlib/__init__.py", line 37, in import_module
    __import__(name)
  File "/Users/ZZJMAC/PycharmProjects/DGCMDB/DGCMDB/urls.py", line 29, in <module>
    url(r'^AppalyCertificate/,AppleCertificate,name=ApplyCertifycate'),
TypeError: url() takes at least 2 arguments (1 given)
2016-06-10 03:08:49,349 [Thread-3:123145310715904] [django.request:256] [base:handle_uncaught_exception] [ERROR]- Internal Server Error: /favicon.ico
Traceback (most recent call last):
  File "/Library/Python/2.7/site-packages/Django-1.8.9-py2.7.egg/django/core/handlers/base.py", line 108, in get_response
    response = middleware_method(request)
  File "/Library/Python/2.7/site-packages/Django-1.8.9-py2.7.egg/django/middleware/common.py", line 74, in process_request
    if (not urlresolvers.is_valid_path(request.path_info, urlconf) and
  File "/Library/Python/2.7/site-packages/Django-1.8.9-py2.7.egg/django/core/urlresolvers.py", line 646, in is_valid_path
    resolve(path, urlconf)
  File "/Library/Python/2.7/site-packages/Django-1.8.9-py2.7.egg/django/core/urlresolvers.py", line 521, in resolve
    return get_resolver(urlconf).resolve(path)
  File "/Library/Python/2.7/site-packages/Django-1.8.9-py2.7.egg/django/core/urlresolvers.py", line 365, in resolve
    for pattern in self.url_patterns:
  File "/Library/Python/2.7/site-packages/Django-1.8.9-py2.7.egg/django/core/urlresolvers.py", line 401, in url_patterns
    patterns = getattr(self.urlconf_module, "urlpatterns", self.urlconf_module)
  File "/Library/Python/2.7/site-packages/Django-1.8.9-py2.7.egg/django/core/urlresolvers.py", line 395, in urlconf_module
    self._urlconf_module = import_module(self.urlconf_name)
  File "/System/Library/Frameworks/Python.framework/Versions/2.7/lib/python2.7/importlib/__init__.py", line 37, in import_module
    __import__(name)
  File "/Users/ZZJMAC/PycharmProjects/DGCMDB/DGCMDB/urls.py", line 29, in <module>
    url(r'^AppalyCertificate/,AppleCertificate,name=ApplyCertifycate'),
TypeError: url() takes at least 2 arguments (1 given)
2016-06-10 03:08:49,574 [Thread-4:123145310715904] [django.request:256] [base:handle_uncaught_exception] [ERROR]- Internal Server Error: /favicon.ico
Traceback (most recent call last):
  File "/Library/Python/2.7/site-packages/Django-1.8.9-py2.7.egg/django/core/handlers/base.py", line 108, in get_response
    response = middleware_method(request)
  File "/Library/Python/2.7/site-packages/Django-1.8.9-py2.7.egg/django/middleware/common.py", line 74, in process_request
    if (not urlresolvers.is_valid_path(request.path_info, urlconf) and
  File "/Library/Python/2.7/site-packages/Django-1.8.9-py2.7.egg/django/core/urlresolvers.py", line 646, in is_valid_path
    resolve(path, urlconf)
  File "/Library/Python/2.7/site-packages/Django-1.8.9-py2.7.egg/django/core/urlresolvers.py", line 521, in resolve
    return get_resolver(urlconf).resolve(path)
  File "/Library/Python/2.7/site-packages/Django-1.8.9-py2.7.egg/django/core/urlresolvers.py", line 365, in resolve
    for pattern in self.url_patterns:
  File "/Library/Python/2.7/site-packages/Django-1.8.9-py2.7.egg/django/core/urlresolvers.py", line 401, in url_patterns
    patterns = getattr(self.urlconf_module, "urlpatterns", self.urlconf_module)
  File "/Library/Python/2.7/site-packages/Django-1.8.9-py2.7.egg/django/core/urlresolvers.py", line 395, in urlconf_module
    self._urlconf_module = import_module(self.urlconf_name)
  File "/System/Library/Frameworks/Python.framework/Versions/2.7/lib/python2.7/importlib/__init__.py", line 37, in import_module
    __import__(name)
  File "/Users/ZZJMAC/PycharmProjects/DGCMDB/DGCMDB/urls.py", line 29, in <module>
    url(r'^AppalyCertificate/,AppleCertificate,name=ApplyCertifycate'),
TypeError: url() takes at least 2 arguments (1 given)
2016-06-10 03:08:56,633 [Thread-5:123145310715904] [django.request:256] [base:handle_uncaught_exception] [ERROR]- Internal Server Error: /index
Traceback (most recent call last):
  File "/Library/Python/2.7/site-packages/Django-1.8.9-py2.7.egg/django/core/handlers/base.py", line 108, in get_response
    response = middleware_method(request)
  File "/Library/Python/2.7/site-packages/Django-1.8.9-py2.7.egg/django/middleware/common.py", line 74, in process_request
    if (not urlresolvers.is_valid_path(request.path_info, urlconf) and
  File "/Library/Python/2.7/site-packages/Django-1.8.9-py2.7.egg/django/core/urlresolvers.py", line 646, in is_valid_path
    resolve(path, urlconf)
  File "/Library/Python/2.7/site-packages/Django-1.8.9-py2.7.egg/django/core/urlresolvers.py", line 521, in resolve
    return get_resolver(urlconf).resolve(path)
  File "/Library/Python/2.7/site-packages/Django-1.8.9-py2.7.egg/django/core/urlresolvers.py", line 365, in resolve
    for pattern in self.url_patterns:
  File "/Library/Python/2.7/site-packages/Django-1.8.9-py2.7.egg/django/core/urlresolvers.py", line 401, in url_patterns
    patterns = getattr(self.urlconf_module, "urlpatterns", self.urlconf_module)
  File "/Library/Python/2.7/site-packages/Django-1.8.9-py2.7.egg/django/core/urlresolvers.py", line 395, in urlconf_module
    self._urlconf_module = import_module(self.urlconf_name)
  File "/System/Library/Frameworks/Python.framework/Versions/2.7/lib/python2.7/importlib/__init__.py", line 37, in import_module
    __import__(name)
  File "/Users/ZZJMAC/PycharmProjects/DGCMDB/DGCMDB/urls.py", line 29, in <module>
    url(r'^AppalyCertificate/,AppleCertificate,name=ApplyCertifycate'),
TypeError: url() takes at least 2 arguments (1 given)
2016-06-10 03:09:27,188 [Thread-11:123145310715904] [django.request:170] [base:get_response] [WARNING]- Not Found: /inc/timming.php
2016-06-10 03:12:26,683 [Thread-2:123145310715904] [django.request:256] [base:handle_uncaught_exception] [ERROR]- Internal Server Error: /ApplyCertificate
Traceback (most recent call last):
  File "/Library/Python/2.7/site-packages/Django-1.8.9-py2.7.egg/django/core/handlers/base.py", line 108, in get_response
    response = middleware_method(request)
  File "/Library/Python/2.7/site-packages/Django-1.8.9-py2.7.egg/django/middleware/common.py", line 74, in process_request
    if (not urlresolvers.is_valid_path(request.path_info, urlconf) and
  File "/Library/Python/2.7/site-packages/Django-1.8.9-py2.7.egg/django/core/urlresolvers.py", line 646, in is_valid_path
    resolve(path, urlconf)
  File "/Library/Python/2.7/site-packages/Django-1.8.9-py2.7.egg/django/core/urlresolvers.py", line 521, in resolve
    return get_resolver(urlconf).resolve(path)
  File "/Library/Python/2.7/site-packages/Django-1.8.9-py2.7.egg/django/core/urlresolvers.py", line 365, in resolve
    for pattern in self.url_patterns:
  File "/Library/Python/2.7/site-packages/Django-1.8.9-py2.7.egg/django/core/urlresolvers.py", line 401, in url_patterns
    patterns = getattr(self.urlconf_module, "urlpatterns", self.urlconf_module)
  File "/Library/Python/2.7/site-packages/Django-1.8.9-py2.7.egg/django/core/urlresolvers.py", line 395, in urlconf_module
    self._urlconf_module = import_module(self.urlconf_name)
  File "/System/Library/Frameworks/Python.framework/Versions/2.7/lib/python2.7/importlib/__init__.py", line 37, in import_module
    __import__(name)
  File "/Users/ZZJMAC/PycharmProjects/DGCMDB/DGCMDB/urls.py", line 29, in <module>
    url(r'^AppalyCertificate/,AppleCertificate,name=ApplyCertifycate'),
TypeError: url() takes at least 2 arguments (1 given)
2016-06-10 03:20:00,505 [Thread-3:123145310715904] [django.request:170] [base:get_response] [WARNING]- Not Found: /ApplyCertificate
2016-06-10 03:20:17,132 [Thread-4:123145310715904] [django.request:170] [base:get_response] [WARNING]- Not Found: /ApplyCertificate/
2016-06-10 03:20:19,962 [Thread-5:123145310715904] [django.request:170] [base:get_response] [WARNING]- Not Found: /ApplyCertificate
2016-06-10 03:20:33,469 [Thread-8:123145310715904] [django.request:170] [base:get_response] [WARNING]- Not Found: /inc/timming.php
2016-06-10 03:51:17,720 [Thread-2:123145310715904] [django.request:256] [base:handle_uncaught_exception] [ERROR]- Internal Server Error: /login
Traceback (most recent call last):
  File "/Library/Python/2.7/site-packages/Django-1.8.9-py2.7.egg/django/core/handlers/base.py", line 108, in get_response
    response = middleware_method(request)
  File "/Library/Python/2.7/site-packages/Django-1.8.9-py2.7.egg/django/middleware/common.py", line 74, in process_request
    if (not urlresolvers.is_valid_path(request.path_info, urlconf) and
  File "/Library/Python/2.7/site-packages/Django-1.8.9-py2.7.egg/django/core/urlresolvers.py", line 646, in is_valid_path
    resolve(path, urlconf)
  File "/Library/Python/2.7/site-packages/Django-1.8.9-py2.7.egg/django/core/urlresolvers.py", line 521, in resolve
    return get_resolver(urlconf).resolve(path)
  File "/Library/Python/2.7/site-packages/Django-1.8.9-py2.7.egg/django/core/urlresolvers.py", line 365, in resolve
    for pattern in self.url_patterns:
  File "/Library/Python/2.7/site-packages/Django-1.8.9-py2.7.egg/django/core/urlresolvers.py", line 401, in url_patterns
    patterns = getattr(self.urlconf_module, "urlpatterns", self.urlconf_module)
  File "/Library/Python/2.7/site-packages/Django-1.8.9-py2.7.egg/django/core/urlresolvers.py", line 395, in urlconf_module
    self._urlconf_module = import_module(self.urlconf_name)
  File "/System/Library/Frameworks/Python.framework/Versions/2.7/lib/python2.7/importlib/__init__.py", line 37, in import_module
    __import__(name)
  File "/Users/ZZJMAC/PycharmProjects/DGCMDB/DGCMDB/urls.py", line 18, in <module>
    from website.views import index,ApplyCertificate,Login
  File "/Users/ZZJMAC/PycharmProjects/DGCMDB/website/views.py", line 20
    if result == 1
                 ^
SyntaxError: invalid syntax
2016-06-10 03:57:55,621 [Thread-3:123145310715904] [django.request:256] [base:handle_uncaught_exception] [ERROR]- Internal Server Error: /login
Traceback (most recent call last):
  File "/Library/Python/2.7/site-packages/Django-1.8.9-py2.7.egg/django/core/handlers/base.py", line 108, in get_response
    response = middleware_method(request)
  File "/Library/Python/2.7/site-packages/Django-1.8.9-py2.7.egg/django/middleware/common.py", line 74, in process_request
    if (not urlresolvers.is_valid_path(request.path_info, urlconf) and
  File "/Library/Python/2.7/site-packages/Django-1.8.9-py2.7.egg/django/core/urlresolvers.py", line 646, in is_valid_path
    resolve(path, urlconf)
  File "/Library/Python/2.7/site-packages/Django-1.8.9-py2.7.egg/django/core/urlresolvers.py", line 521, in resolve
    return get_resolver(urlconf).resolve(path)
  File "/Library/Python/2.7/site-packages/Django-1.8.9-py2.7.egg/django/core/urlresolvers.py", line 365, in resolve
    for pattern in self.url_patterns:
  File "/Library/Python/2.7/site-packages/Django-1.8.9-py2.7.egg/django/core/urlresolvers.py", line 401, in url_patterns
    patterns = getattr(self.urlconf_module, "urlpatterns", self.urlconf_module)
  File "/Library/Python/2.7/site-packages/Django-1.8.9-py2.7.egg/django/core/urlresolvers.py", line 395, in urlconf_module
    self._urlconf_module = import_module(self.urlconf_name)
  File "/System/Library/Frameworks/Python.framework/Versions/2.7/lib/python2.7/importlib/__init__.py", line 37, in import_module
    __import__(name)
  File "/Users/ZZJMAC/PycharmProjects/DGCMDB/DGCMDB/urls.py", line 18, in <module>
    from website.views import index,ApplyCertificate,Login
  File "/Users/ZZJMAC/PycharmProjects/DGCMDB/website/views.py", line 21
SyntaxError: Non-ASCII character '\xe7' in file /Users/ZZJMAC/PycharmProjects/DGCMDB/website/views.py on line 21, but no encoding declared; see http://python.org/dev/peps/pep-0263/ for details
2016-06-10 03:58:44,446 [Thread-4:123145310715904] [django.request:256] [base:handle_uncaught_exception] [ERROR]- Internal Server Error: /login
Traceback (most recent call last):
  File "/Library/Python/2.7/site-packages/Django-1.8.9-py2.7.egg/django/core/handlers/base.py", line 108, in get_response
    response = middleware_method(request)
  File "/Library/Python/2.7/site-packages/Django-1.8.9-py2.7.egg/django/middleware/common.py", line 74, in process_request
    if (not urlresolvers.is_valid_path(request.path_info, urlconf) and
  File "/Library/Python/2.7/site-packages/Django-1.8.9-py2.7.egg/django/core/urlresolvers.py", line 646, in is_valid_path
    resolve(path, urlconf)
  File "/Library/Python/2.7/site-packages/Django-1.8.9-py2.7.egg/django/core/urlresolvers.py", line 521, in resolve
    return get_resolver(urlconf).resolve(path)
  File "/Library/Python/2.7/site-packages/Django-1.8.9-py2.7.egg/django/core/urlresolvers.py", line 365, in resolve
    for pattern in self.url_patterns:
  File "/Library/Python/2.7/site-packages/Django-1.8.9-py2.7.egg/django/core/urlresolvers.py", line 401, in url_patterns
    patterns = getattr(self.urlconf_module, "urlpatterns", self.urlconf_module)
  File "/Library/Python/2.7/site-packages/Django-1.8.9-py2.7.egg/django/core/urlresolvers.py", line 395, in urlconf_module
    self._urlconf_module = import_module(self.urlconf_name)
  File "/System/Library/Frameworks/Python.framework/Versions/2.7/lib/python2.7/importlib/__init__.py", line 37, in import_module
    __import__(name)
  File "/Users/ZZJMAC/PycharmProjects/DGCMDB/DGCMDB/urls.py", line 18, in <module>
    from website.views import index,ApplyCertificate,Login
  File "/Users/ZZJMAC/PycharmProjects/DGCMDB/website/views.py", line 22
SyntaxError: Non-ASCII character '\xe7' in file /Users/ZZJMAC/PycharmProjects/DGCMDB/website/views.py on line 22, but no encoding declared; see http://python.org/dev/peps/pep-0263/ for details
2016-06-10 04:00:41,131 [Thread-7:123145310715904] [django.request:98] [csrf:_reject] [WARNING]- Forbidden (CSRF cookie not set.): /login/
2016-06-10 04:01:07,452 [Thread-3:123145310715904] [django.request:256] [base:handle_uncaught_exception] [ERROR]- Internal Server Error: /login/
Traceback (most recent call last):
  File "/Library/Python/2.7/site-packages/Django-1.8.9-py2.7.egg/django/core/handlers/base.py", line 132, in get_response
    response = wrapped_callback(request, *callback_args, **callback_kwargs)
  File "/Users/ZZJMAC/PycharmProjects/DGCMDB/website/views.py", line 20, in Login
    result = UserInfo.objects.filter(username= user,password=pwd).count()
  File "/Library/Python/2.7/site-packages/Django-1.8.9-py2.7.egg/django/db/models/manager.py", line 127, in manager_method
    return getattr(self.get_queryset(), name)(*args, **kwargs)
  File "/Library/Python/2.7/site-packages/Django-1.8.9-py2.7.egg/django/db/models/query.py", line 679, in filter
    return self._filter_or_exclude(False, *args, **kwargs)
  File "/Library/Python/2.7/site-packages/Django-1.8.9-py2.7.egg/django/db/models/query.py", line 697, in _filter_or_exclude
    clone.query.add_q(Q(*args, **kwargs))
  File "/Library/Python/2.7/site-packages/Django-1.8.9-py2.7.egg/django/db/models/sql/query.py", line 1310, in add_q
    clause, require_inner = self._add_q(where_part, self.used_aliases)
  File "/Library/Python/2.7/site-packages/Django-1.8.9-py2.7.egg/django/db/models/sql/query.py", line 1338, in _add_q
    allow_joins=allow_joins, split_subq=split_subq,
  File "/Library/Python/2.7/site-packages/Django-1.8.9-py2.7.egg/django/db/models/sql/query.py", line 1150, in build_filter
    lookups, parts, reffed_expression = self.solve_lookup_type(arg)
  File "/Library/Python/2.7/site-packages/Django-1.8.9-py2.7.egg/django/db/models/sql/query.py", line 1036, in solve_lookup_type
    _, field, _, lookup_parts = self.names_to_path(lookup_splitted, self.get_meta())
  File "/Library/Python/2.7/site-packages/Django-1.8.9-py2.7.egg/django/db/models/sql/query.py", line 1397, in names_to_path
    "Choices are: %s" % (name, ", ".join(available)))
FieldError: Cannot resolve keyword 'username' into field. Choices are: CreateDate, LoginIP, Logintime, Super, id, pwd, user, work
2016-06-10 04:03:06,881 [Thread-3:123145310715904] [django.request:256] [base:handle_uncaught_exception] [ERROR]- Internal Server Error: /login/
Traceback (most recent call last):
  File "/Library/Python/2.7/site-packages/Django-1.8.9-py2.7.egg/django/core/handlers/base.py", line 132, in get_response
    response = wrapped_callback(request, *callback_args, **callback_kwargs)
  File "/Users/ZZJMAC/PycharmProjects/DGCMDB/website/views.py", line 20, in Login
    result = UserInfo.objects.filter(user=user,pwd=pwd).count()
  File "/Library/Python/2.7/site-packages/Django-1.8.9-py2.7.egg/django/db/models/query.py", line 318, in count
    return self.query.get_count(using=self.db)
  File "/Library/Python/2.7/site-packages/Django-1.8.9-py2.7.egg/django/db/models/sql/query.py", line 466, in get_count
    number = obj.get_aggregation(using, ['__count'])['__count']
  File "/Library/Python/2.7/site-packages/Django-1.8.9-py2.7.egg/django/db/models/sql/query.py", line 447, in get_aggregation
    result = compiler.execute_sql(SINGLE)
  File "/Library/Python/2.7/site-packages/Django-1.8.9-py2.7.egg/django/db/models/sql/compiler.py", line 840, in execute_sql
    cursor.execute(sql, params)
  File "/Library/Python/2.7/site-packages/Django-1.8.9-py2.7.egg/django/db/backends/utils.py", line 79, in execute
    return super(CursorDebugWrapper, self).execute(sql, params)
  File "/Library/Python/2.7/site-packages/Django-1.8.9-py2.7.egg/django/db/backends/utils.py", line 64, in execute
    return self.cursor.execute(sql, params)
  File "/Library/Python/2.7/site-packages/Django-1.8.9-py2.7.egg/django/db/utils.py", line 98, in __exit__
    six.reraise(dj_exc_type, dj_exc_value, traceback)
  File "/Library/Python/2.7/site-packages/Django-1.8.9-py2.7.egg/django/db/backends/utils.py", line 64, in execute
    return self.cursor.execute(sql, params)
  File "/Library/Python/2.7/site-packages/Django-1.8.9-py2.7.egg/django/db/backends/mysql/base.py", line 124, in execute
    return self.cursor.execute(query, args)
  File "/Library/Python/2.7/site-packages/MySQL_python-1.2.4b4-py2.7-macosx-10.11-intel.egg/MySQLdb/cursors.py", line 202, in execute
    self.errorhandler(self, exc, value)
  File "/Library/Python/2.7/site-packages/MySQL_python-1.2.4b4-py2.7-macosx-10.11-intel.egg/MySQLdb/connections.py", line 36, in defaulterrorhandler
    raise errorclass, errorvalue
OperationalError: (1054, "Unknown column 'website_userinfo.pwd' in 'where clause'")
2016-06-10 06:16:51,625 [Thread-2:123145310715904] [django.request:256] [base:handle_uncaught_exception] [ERROR]- Internal Server Error: /adduser
Traceback (most recent call last):
  File "/Library/Python/2.7/site-packages/Django-1.8.9-py2.7.egg/django/core/handlers/base.py", line 108, in get_response
    response = middleware_method(request)
  File "/Library/Python/2.7/site-packages/Django-1.8.9-py2.7.egg/django/middleware/common.py", line 74, in process_request
    if (not urlresolvers.is_valid_path(request.path_info, urlconf) and
  File "/Library/Python/2.7/site-packages/Django-1.8.9-py2.7.egg/django/core/urlresolvers.py", line 646, in is_valid_path
    resolve(path, urlconf)
  File "/Library/Python/2.7/site-packages/Django-1.8.9-py2.7.egg/django/core/urlresolvers.py", line 521, in resolve
    return get_resolver(urlconf).resolve(path)
  File "/Library/Python/2.7/site-packages/Django-1.8.9-py2.7.egg/django/core/urlresolvers.py", line 365, in resolve
    for pattern in self.url_patterns:
  File "/Library/Python/2.7/site-packages/Django-1.8.9-py2.7.egg/django/core/urlresolvers.py", line 401, in url_patterns
    patterns = getattr(self.urlconf_module, "urlpatterns", self.urlconf_module)
  File "/Library/Python/2.7/site-packages/Django-1.8.9-py2.7.egg/django/core/urlresolvers.py", line 395, in urlconf_module
    self._urlconf_module = import_module(self.urlconf_name)
  File "/System/Library/Frameworks/Python.framework/Versions/2.7/lib/python2.7/importlib/__init__.py", line 37, in import_module
    __import__(name)
  File "/Users/ZZJMAC/PycharmProjects/DGCMDB/DGCMDB/urls.py", line 18, in <module>
    from website.views import index,ApplyCertificate,Login,Adduser
  File "/Users/ZZJMAC/PycharmProjects/DGCMDB/website/views.py", line 6, in <module>
    from website.forms import AdduserForm
  File "/Users/ZZJMAC/PycharmProjects/DGCMDB/website/forms.py", line 5, in <module>
    class AdduserForm(forms.form):
AttributeError: 'module' object has no attribute 'form'
2016-06-10 06:18:04,692 [Thread-5:123145310715904] [django.request:256] [base:handle_uncaught_exception] [ERROR]- Internal Server Error: /adduser/
Traceback (most recent call last):
  File "/Library/Python/2.7/site-packages/Django-1.8.9-py2.7.egg/django/core/handlers/base.py", line 151, in get_response
    % (callback.__module__, view_name))
ValueError: The view website.views.Adduser didn't return an HttpResponse object. It returned None instead.
2016-06-10 06:44:28,857 [Thread-5:123145310715904] [django.request:170] [base:get_response] [WARNING]- Not Found: /inc/timming.php
2016-06-10 10:17:05,000 [Thread-15:123145310715904] [django.request:170] [base:get_response] [WARNING]- Not Found: /inc/timming.php
2016-06-10 10:17:40,571 [Thread-17:123145310715904] [django.request:170] [base:get_response] [WARNING]- Not Found: /inc/timming.php
2016-06-10 10:45:59,941 [Thread-2:123145310715904] [django.request:256] [base:handle_uncaught_exception] [ERROR]- Internal Server Error: /adduser/
Traceback (most recent call last):
  File "/Library/Python/2.7/site-packages/Django-1.8.9-py2.7.egg/django/core/handlers/base.py", line 132, in get_response
    response = wrapped_callback(request, *callback_args, **callback_kwargs)
  File "/Users/ZZJMAC/PycharmProjects/DGCMDB/website/views.py", line 39, in Adduser
    return render_to_response('adduser.html', {'form': '用户名存在'})
  File "/Library/Python/2.7/site-packages/Django-1.8.9-py2.7.egg/django/shortcuts.py", line 39, in render_to_response
    content = loader.render_to_string(template_name, context, using=using)
  File "/Library/Python/2.7/site-packages/Django-1.8.9-py2.7.egg/django/template/loader.py", line 98, in render_to_string
    template = get_template(template_name, using=using)
  File "/Library/Python/2.7/site-packages/Django-1.8.9-py2.7.egg/django/template/loader.py", line 35, in get_template
    return engine.get_template(template_name, dirs)
  File "/Library/Python/2.7/site-packages/Django-1.8.9-py2.7.egg/django/template/backends/django.py", line 30, in get_template
    return Template(self.engine.get_template(template_name, dirs))
  File "/Library/Python/2.7/site-packages/Django-1.8.9-py2.7.egg/django/template/engine.py", line 167, in get_template
    template, origin = self.find_template(template_name, dirs)
  File "/Library/Python/2.7/site-packages/Django-1.8.9-py2.7.egg/django/template/engine.py", line 141, in find_template
    source, display_name = loader(name, dirs)
  File "/Library/Python/2.7/site-packages/Django-1.8.9-py2.7.egg/django/template/loaders/base.py", line 13, in __call__
    return self.load_template(template_name, template_dirs)
  File "/Library/Python/2.7/site-packages/Django-1.8.9-py2.7.egg/django/template/loaders/base.py", line 23, in load_template
    template = Template(source, origin, template_name, self.engine)
  File "/Library/Python/2.7/site-packages/Django-1.8.9-py2.7.egg/django/template/base.py", line 191, in __init__
    self.nodelist = engine.compile_string(template_string, origin)
  File "/Library/Python/2.7/site-packages/Django-1.8.9-py2.7.egg/django/template/engine.py", line 261, in compile_string
    return parser.parse()
  File "/Library/Python/2.7/site-packages/Django-1.8.9-py2.7.egg/django/template/base.py", line 342, in parse
    compiled_result = compile_func(self, token)
  File "/Library/Python/2.7/site-packages/Django-1.8.9-py2.7.egg/django/template/defaulttags.py", line 1163, in load
    (taglib, e))
TemplateSyntaxError: 'form.py' is not a valid tag library: Template library form.py not found, tried django.templatetags.form.py,django.contrib.admin.templatetags.form.py,django.contrib.staticfiles.templatetags.form.py
2016-06-10 13:15:35,414 [Thread-3:123145310715904] [django.request:170] [base:get_response] [WARNING]- Not Found: /inc/timming.php
2016-06-10 21:13:55,156 [Thread-2:123145310715904] [django.request:170] [base:get_response] [WARNING]- Not Found: /adddata
2016-06-10 21:14:40,032 [Thread-3:123145310715904] [django.request:170] [base:get_response] [WARNING]- Not Found: /adddata/zzj
2016-06-10 21:14:46,227 [Thread-5:123145310715904] [django.request:256] [base:handle_uncaught_exception] [ERROR]- Internal Server Error: /adddata/123/
Traceback (most recent call last):
  File "/Library/Python/2.7/site-packages/Django-1.8.9-py2.7.egg/django/core/handlers/base.py", line 132, in get_response
    response = wrapped_callback(request, *callback_args, **callback_kwargs)
TypeError: list() takes at most 1 argument (2 given)
2016-06-10 21:17:59,813 [Thread-6:123145310715904] [django.request:170] [base:get_response] [WARNING]- Not Found: /adddata/asd
2016-06-10 21:18:05,539 [Thread-8:123145310715904] [django.request:256] [base:handle_uncaught_exception] [ERROR]- Internal Server Error: /adddata/123222/
Traceback (most recent call last):
  File "/Library/Python/2.7/site-packages/Django-1.8.9-py2.7.egg/django/core/handlers/base.py", line 132, in get_response
    response = wrapped_callback(request, *callback_args, **callback_kwargs)
TypeError: list() takes at most 1 argument (2 given)
2016-06-10 21:29:28,242 [Thread-8:123145310715904] [django.request:170] [base:get_response] [WARNING]- Not Found: /inc/timming.php
2016-06-10 21:52:29,692 [Thread-2:123145310715904] [django.request:170] [base:get_response] [WARNING]- Not Found: /getdata
2016-06-10 21:57:13,948 [Thread-2:123145310715904] [django.request:256] [base:handle_uncaught_exception] [ERROR]- Internal Server Error: /getdata/4/
Traceback (most recent call last):
  File "/Library/Python/2.7/site-packages/Django-1.8.9-py2.7.egg/django/core/handlers/base.py", line 119, in get_response
    resolver_match = resolver.resolve(request.path_info)
  File "/Library/Python/2.7/site-packages/Django-1.8.9-py2.7.egg/django/core/urlresolvers.py", line 365, in resolve
    for pattern in self.url_patterns:
  File "/Library/Python/2.7/site-packages/Django-1.8.9-py2.7.egg/django/core/urlresolvers.py", line 401, in url_patterns
    patterns = getattr(self.urlconf_module, "urlpatterns", self.urlconf_module)
  File "/Library/Python/2.7/site-packages/Django-1.8.9-py2.7.egg/django/core/urlresolvers.py", line 395, in urlconf_module
    self._urlconf_module = import_module(self.urlconf_name)
  File "/System/Library/Frameworks/Python.framework/Versions/2.7/lib/python2.7/importlib/__init__.py", line 37, in import_module
    __import__(name)
  File "/Users/ZZJMAC/PycharmProjects/DGCMDB/DGCMDB/urls.py", line 18, in <module>
    from website.views import index,ApplyCertificate,Login,Adduser,Adddata,Deldata,Update,Getdata
  File "/Users/ZZJMAC/PycharmProjects/DGCMDB/website/views.py", line 65
    for item in assetList
                        ^
SyntaxError: invalid syntax
2016-06-10 21:57:33,731 [Thread-3:123145310715904] [django.request:256] [base:handle_uncaught_exception] [ERROR]- Internal Server Error: /getdata/4/
Traceback (most recent call last):
  File "/Library/Python/2.7/site-packages/Django-1.8.9-py2.7.egg/django/core/handlers/base.py", line 132, in get_response
    response = wrapped_callback(request, *callback_args, **callback_kwargs)
  File "/Users/ZZJMAC/PycharmProjects/DGCMDB/website/views.py", line 66, in Getdata
    print assetList.id
AttributeError: 'QuerySet' object has no attribute 'id'
2016-06-10 21:57:36,642 [Thread-4:123145310715904] [django.request:256] [base:handle_uncaught_exception] [ERROR]- Internal Server Error: /getdata/4/
Traceback (most recent call last):
  File "/Library/Python/2.7/site-packages/Django-1.8.9-py2.7.egg/django/core/handlers/base.py", line 132, in get_response
    response = wrapped_callback(request, *callback_args, **callback_kwargs)
  File "/Users/ZZJMAC/PycharmProjects/DGCMDB/website/views.py", line 66, in Getdata
    print assetList.id
AttributeError: 'QuerySet' object has no attribute 'id'
2016-06-10 21:59:26,345 [Thread-2:123145310715904] [django.request:256] [base:handle_uncaught_exception] [ERROR]- Internal Server Error: /getdata/4/
Traceback (most recent call last):
  File "/Library/Python/2.7/site-packages/Django-1.8.9-py2.7.egg/django/core/handlers/base.py", line 132, in get_response
    response = wrapped_callback(request, *callback_args, **callback_kwargs)
  File "/Users/ZZJMAC/PycharmProjects/DGCMDB/website/views.py", line 66, in Getdata
    print assetList.id
AttributeError: 'QuerySet' object has no attribute 'id'
2016-06-10 22:02:28,336 [Thread-6:123145310715904] [django.request:256] [base:handle_uncaught_exception] [ERROR]- Internal Server Error: /getdata/1/
Traceback (most recent call last):
  File "/Library/Python/2.7/site-packages/Django-1.8.9-py2.7.egg/django/core/handlers/base.py", line 132, in get_response
    response = wrapped_callback(request, *callback_args, **callback_kwargs)
  File "/Users/ZZJMAC/PycharmProjects/DGCMDB/website/views.py", line 67, in Getdata
    return HttpResponse(item.id)
UnboundLocalError: local variable 'item' referenced before assignment
2016-06-10 22:04:03,016 [Thread-4:123145310715904] [django.request:170] [base:get_response] [WARNING]- Not Found: /getdata/s/
2016-06-11 00:21:17,771 [Thread-2:123145310715904] [django.request:256] [base:handle_uncaught_exception] [ERROR]- Internal Server Error: /assetlist
Traceback (most recent call last):
  File "/Library/Python/2.7/site-packages/Django-1.8.9-py2.7.egg/django/core/handlers/base.py", line 108, in get_response
    response = middleware_method(request)
  File "/Library/Python/2.7/site-packages/Django-1.8.9-py2.7.egg/django/middleware/common.py", line 74, in process_request
    if (not urlresolvers.is_valid_path(request.path_info, urlconf) and
  File "/Library/Python/2.7/site-packages/Django-1.8.9-py2.7.egg/django/core/urlresolvers.py", line 646, in is_valid_path
    resolve(path, urlconf)
  File "/Library/Python/2.7/site-packages/Django-1.8.9-py2.7.egg/django/core/urlresolvers.py", line 521, in resolve
    return get_resolver(urlconf).resolve(path)
  File "/Library/Python/2.7/site-packages/Django-1.8.9-py2.7.egg/django/core/urlresolvers.py", line 365, in resolve
    for pattern in self.url_patterns:
  File "/Library/Python/2.7/site-packages/Django-1.8.9-py2.7.egg/django/core/urlresolvers.py", line 401, in url_patterns
    patterns = getattr(self.urlconf_module, "urlpatterns", self.urlconf_module)
  File "/Library/Python/2.7/site-packages/Django-1.8.9-py2.7.egg/django/core/urlresolvers.py", line 395, in urlconf_module
    self._urlconf_module = import_module(self.urlconf_name)
  File "/System/Library/Frameworks/Python.framework/Versions/2.7/lib/python2.7/importlib/__init__.py", line 37, in import_module
    __import__(name)
  File "/Users/ZZJMAC/PycharmProjects/DGCMDB/DGCMDB/urls.py", line 36, in <module>
    url(r'^assetlist/$',AssetList()),
TypeError: AssetList() takes exactly 1 argument (0 given)
2016-06-11 06:08:46,545 [Thread-8:123145310715904] [django.request:170] [base:get_response] [WARNING]- Not Found: /inc/timming.php
2016-06-11 06:10:37,206 [Thread-10:123145310715904] [django.request:170] [base:get_response] [WARNING]- Not Found: /inc/timming.php
2016-06-11 07:54:14,914 [Thread-3:123145310715904] [django.request:170] [base:get_response] [WARNING]- Not Found: /templates/adduser.html
2016-06-11 07:54:39,412 [Thread-4:123145310715904] [django.request:170] [base:get_response] [WARNING]- Not Found: /templates/adduser.html
2016-06-11 07:58:19,874 [Thread-3:123145310715904] [django.request:170] [base:get_response] [WARNING]- Not Found: /templates/adduser.html
2016-06-11 11:04:20,610 [Thread-3:123145310715904] [django.request:170] [base:get_response] [WARNING]- Not Found: /templates/adduser.html
2016-06-11 11:07:48,627 [Thread-7:123145310715904] [django.request:170] [base:get_response] [WARNING]- Not Found: /templates/adduser.html
2016-06-11 11:08:37,452 [Thread-8:123145310715904] [django.request:170] [base:get_response] [WARNING]- Not Found: /templates/adduser.html
2016-06-11 11:11:37,507 [Thread-9:123145310715904] [django.request:170] [base:get_response] [WARNING]- Not Found: /templates/adduser.html
2016-06-11 11:11:42,502 [Thread-11:123145310715904] [django.request:170] [base:get_response] [WARNING]- Not Found: /adduser/Adduser
2016-06-11 11:11:54,607 [Thread-13:123145310715904] [django.request:170] [base:get_response] [WARNING]- Not Found: /adduser/Adduser
2016-06-11 11:18:57,880 [Thread-3:123145310715904] [django.request:170] [base:get_response] [WARNING]- Not Found: /adduser/Adduser
2016-06-11 11:19:27,909 [Thread-4:123145310715904] [django.request:170] [base:get_response] [WARNING]- Not Found: /adduser/Adduser
2016-06-11 11:37:48,295 [Thread-5:123145310715904] [django.request:170] [base:get_response] [WARNING]- Not Found: /Adduser/
2016-06-11 11:44:55,438 [Thread-4:123145310715904] [django.request:256] [base:handle_uncaught_exception] [ERROR]- Internal Server Error: /adduser/
Traceback (most recent call last):
  File "/Library/Python/2.7/site-packages/Django-1.8.9-py2.7.egg/django/core/handlers/base.py", line 132, in get_response
    response = wrapped_callback(request, *callback_args, **callback_kwargs)
  File "/Users/ZZJMAC/PycharmProjects/DGCMDB/website/views.py", line 41, in Adduser
    UserInfo.objects.create(user=username,pwd=email)
  File "/Library/Python/2.7/site-packages/Django-1.8.9-py2.7.egg/django/db/models/manager.py", line 127, in manager_method
    return getattr(self.get_queryset(), name)(*args, **kwargs)
  File "/Library/Python/2.7/site-packages/Django-1.8.9-py2.7.egg/django/db/models/query.py", line 348, in create
    obj.save(force_insert=True, using=self.db)
  File "/Library/Python/2.7/site-packages/Django-1.8.9-py2.7.egg/django/db/models/base.py", line 734, in save
    force_update=force_update, update_fields=update_fields)
  File "/Library/Python/2.7/site-packages/Django-1.8.9-py2.7.egg/django/db/models/base.py", line 762, in save_base
    updated = self._save_table(raw, cls, force_insert, force_update, using, update_fields)
  File "/Library/Python/2.7/site-packages/Django-1.8.9-py2.7.egg/django/db/models/base.py", line 846, in _save_table
    result = self._do_insert(cls._base_manager, using, fields, update_pk, raw)
  File "/Library/Python/2.7/site-packages/Django-1.8.9-py2.7.egg/django/db/models/base.py", line 885, in _do_insert
    using=using, raw=raw)
  File "/Library/Python/2.7/site-packages/Django-1.8.9-py2.7.egg/django/db/models/manager.py", line 127, in manager_method
    return getattr(self.get_queryset(), name)(*args, **kwargs)
  File "/Library/Python/2.7/site-packages/Django-1.8.9-py2.7.egg/django/db/models/query.py", line 920, in _insert
    return query.get_compiler(using=using).execute_sql(return_id)
  File "/Library/Python/2.7/site-packages/Django-1.8.9-py2.7.egg/django/db/models/sql/compiler.py", line 974, in execute_sql
    cursor.execute(sql, params)
  File "/Library/Python/2.7/site-packages/Django-1.8.9-py2.7.egg/django/db/backends/utils.py", line 79, in execute
    return super(CursorDebugWrapper, self).execute(sql, params)
  File "/Library/Python/2.7/site-packages/Django-1.8.9-py2.7.egg/django/db/backends/utils.py", line 64, in execute
    return self.cursor.execute(sql, params)
  File "/Library/Python/2.7/site-packages/Django-1.8.9-py2.7.egg/django/db/utils.py", line 98, in __exit__
    six.reraise(dj_exc_type, dj_exc_value, traceback)
  File "/Library/Python/2.7/site-packages/Django-1.8.9-py2.7.egg/django/db/backends/utils.py", line 64, in execute
    return self.cursor.execute(sql, params)
  File "/Library/Python/2.7/site-packages/Django-1.8.9-py2.7.egg/django/db/backends/mysql/base.py", line 124, in execute
    return self.cursor.execute(query, args)
  File "/Library/Python/2.7/site-packages/MySQL_python-1.2.4b4-py2.7-macosx-10.11-intel.egg/MySQLdb/cursors.py", line 202, in execute
    self.errorhandler(self, exc, value)
  File "/Library/Python/2.7/site-packages/MySQL_python-1.2.4b4-py2.7-macosx-10.11-intel.egg/MySQLdb/connections.py", line 36, in defaulterrorhandler
    raise errorclass, errorvalue
IntegrityError: (1062, "Duplicate entry '123' for key 'website_userinfo_user_1dbe5893b9081341_uniq'")
2016-06-11 12:17:15,105 [Thread-6:123145310715904] [django.request:256] [base:handle_uncaught_exception] [ERROR]- Internal Server Error: /adduser/
Traceback (most recent call last):
  File "/Library/Python/2.7/site-packages/Django-1.8.9-py2.7.egg/django/core/handlers/base.py", line 132, in get_response
    response = wrapped_callback(request, *callback_args, **callback_kwargs)
  File "/Users/ZZJMAC/PycharmProjects/DGCMDB/website/views.py", line 45, in Adduser
    return render_to_response('adduser.html', {'form': adduserform},{'status':'用户名已存在'})
  File "/Library/Python/2.7/site-packages/Django-1.8.9-py2.7.egg/django/shortcuts.py", line 45, in render_to_response
    using=using)
  File "/Library/Python/2.7/site-packages/Django-1.8.9-py2.7.egg/django/template/loader.py", line 115, in render_to_string
    template_name, context, context_instance, dirs, dictionary)
  File "/Library/Python/2.7/site-packages/Django-1.8.9-py2.7.egg/django/template/engine.py", line 220, in render_to_string
    with context_instance.push(context):
AttributeError: 'dict' object has no attribute 'push'
2016-06-11 12:23:20,411 [Thread-2:123145310715904] [django.request:256] [base:handle_uncaught_exception] [ERROR]- Internal Server Error: /adduser/
Traceback (most recent call last):
  File "/Library/Python/2.7/site-packages/Django-1.8.9-py2.7.egg/django/core/handlers/base.py", line 132, in get_response
    response = wrapped_callback(request, *callback_args, **callback_kwargs)
  File "/Users/ZZJMAC/PycharmProjects/DGCMDB/website/views.py", line 44, in Adduser
    return render_to_response({'status':'用户名已存在'})
  File "/Library/Python/2.7/site-packages/Django-1.8.9-py2.7.egg/django/shortcuts.py", line 39, in render_to_response
    content = loader.render_to_string(template_name, context, using=using)
  File "/Library/Python/2.7/site-packages/Django-1.8.9-py2.7.egg/django/template/loader.py", line 98, in render_to_string
    template = get_template(template_name, using=using)
  File "/Library/Python/2.7/site-packages/Django-1.8.9-py2.7.egg/django/template/loader.py", line 46, in get_template
    raise TemplateDoesNotExist(template_name)
TemplateDoesNotExist: {'status': '\xe7\x94\xa8\xe6\x88\xb7\xe5\x90\x8d\xe5\xb7\xb2\xe5\xad\x98\xe5\x9c\xa8'}
2016-06-11 12:23:28,093 [Thread-4:123145310715904] [django.request:256] [base:handle_uncaught_exception] [ERROR]- Internal Server Error: /adduser/
Traceback (most recent call last):
  File "/Library/Python/2.7/site-packages/Django-1.8.9-py2.7.egg/django/core/handlers/base.py", line 132, in get_response
    response = wrapped_callback(request, *callback_args, **callback_kwargs)
  File "/Users/ZZJMAC/PycharmProjects/DGCMDB/website/views.py", line 44, in Adduser
    return render_to_response({'status':'用户名已存在'})
  File "/Library/Python/2.7/site-packages/Django-1.8.9-py2.7.egg/django/shortcuts.py", line 39, in render_to_response
    content = loader.render_to_string(template_name, context, using=using)
  File "/Library/Python/2.7/site-packages/Django-1.8.9-py2.7.egg/django/template/loader.py", line 98, in render_to_string
    template = get_template(template_name, using=using)
  File "/Library/Python/2.7/site-packages/Django-1.8.9-py2.7.egg/django/template/loader.py", line 46, in get_template
    raise TemplateDoesNotExist(template_name)
TemplateDoesNotExist: {'status': '\xe7\x94\xa8\xe6\x88\xb7\xe5\x90\x8d\xe5\xb7\xb2\xe5\xad\x98\xe5\x9c\xa8'}
2016-06-12 01:05:15,387 [Thread-3:123145310715904] [django.request:182] [base:get_response] [WARNING]- Not Found: /inc/timming.php
2016-06-12 01:05:29,187 [Thread-4:123145310715904] [django.request:182] [base:get_response] [WARNING]- Not Found: /ApplyCertificate
2016-06-12 01:14:11,673 [Thread-2:123145310715904] [django.request:182] [base:get_response] [WARNING]- Not Found: /ApplyCertificate
2016-06-12 01:14:48,855 [Thread-3:123145310715904] [django.request:182] [base:get_response] [WARNING]- Not Found: /ApplyCertificate
2016-06-12 01:17:25,117 [Thread-2:123145310715904] [django.request:182] [base:get_response] [WARNING]- Not Found: /applycertificate
2016-06-12 01:17:30,266 [Thread-3:123145310715904] [django.request:182] [base:get_response] [WARNING]- Not Found: /applycertificate
2016-06-12 01:17:50,538 [Thread-2:123145310715904] [django.request:182] [base:get_response] [WARNING]- Not Found: /applycertificate
2016-06-12 01:17:50,821 [Thread-4:123145310715904] [django.request:182] [base:get_response] [WARNING]- Not Found: /inc/timming.php
2016-06-12 03:26:00,409 [Thread-3:123145314922496] [django.request:182] [base:get_response] [WARNING]- Not Found: /inc/timming.php
2016-06-12 03:28:12,793 [Thread-9:123145310715904] [django.request:182] [base:get_response] [WARNING]- Not Found: /inc/timming.php
2016-06-12 04:01:42,470 [Thread-3:123145310715904] [django.request:182] [base:get_response] [WARNING]- Not Found: /inc/timming.php
2016-06-12 04:25:07,182 [Thread-7:123145310715904] [django.request:182] [base:get_response] [WARNING]- Not Found: /inc/timming.php
2016-06-12 04:27:37,991 [Thread-7:123145310715904] [django.request:182] [base:get_response] [WARNING]- Not Found: /inc/timming.php
2016-06-12 04:28:56,534 [Thread-9:123145310715904] [django.request:182] [base:get_response] [WARNING]- Not Found: /inc/timming.php
2016-06-12 04:30:18,166 [Thread-9:123145310715904] [django.request:182] [base:get_response] [WARNING]- Not Found: /inc/timming.php
2016-06-12 08:08:01,859 [Thread-7:123145310715904] [django.request:182] [base:get_response] [WARNING]- Not Found: /inc/timming.php
2016-06-12 08:19:39,191 [Thread-7:123145310715904] [django.request:182] [base:get_response] [WARNING]- Not Found: /inc/timming.php
2016-06-12 08:21:01,674 [Thread-3:123145310715904] [django.request:182] [base:get_response] [WARNING]- Not Found: /inc/timming.php
2016-06-12 08:21:51,428 [Thread-3:123145310715904] [django.request:182] [base:get_response] [WARNING]- Not Found: /inc/timming.php
2016-06-12 08:22:54,357 [Thread-3:123145310715904] [django.request:182] [base:get_response] [WARNING]- Not Found: /inc/timming.php
2016-06-12 08:23:49,601 [Thread-6:123145310715904] [django.request:182] [base:get_response] [WARNING]- Not Found: /inc/timming.php
2016-06-12 08:43:19,890 [Thread-2:123145310715904] [django.request:182] [base:get_response] [WARNING]- Not Found: /admin
2016-06-12 08:51:32,246 [Thread-26:123145310715904] [django.request:182] [base:get_response] [WARNING]- Not Found: /inc/timming.php
